<?xml version="1.0" ?>
<!-- =================================================================================== -->
<!-- |    This document was autogenerated by xacro from osr.urdf.xacro                 | -->
<!-- |    EDITING THIS FILE BY HAND IS NOT RECOMMENDED                                 | -->
<!-- =================================================================================== -->
<robot name="rover">
  <material name="black">
    <color rgba="0.1 0.1 0.1 1.0"/>
  </material>
  <material name="blue">
    <color rgba="0 0 1 0.5"/>
  </material>
  <material name="sky_blue">
    <color rgba="0.5294 0.8078 0.9804 1"/>
  </material>
  <material name="silver">
    <color rgba="0.75 0.75 0.75 1"/>
  </material>
  <material name="brown">
    <color rgba="0.5451 0.2706 0.0745 1"/>
  </material>
  <ros2_control name="GazeboSystem" type="system">
    <hardware>
      <plugin>gazebo_ros2_control/GazeboSystem</plugin>
    </hardware>
    <joint name="middle_wheel_joint_left">
      <command_interface name="velocity">
        <param name="min">-10</param>
        <param name="max">10</param>
      </command_interface>
      <state_interface name="position"/>
      <state_interface name="velocity"/>
    </joint>
    <joint name="middle_wheel_joint_right">
      <command_interface name="velocity">
        <param name="min">-10</param>
        <param name="max">10</param>
      </command_interface>
      <state_interface name="position"/>
      <state_interface name="velocity"/>
      <state_interface name="effort"/>
    </joint>
    <joint name="rear_wheel_joint_left">
      <command_interface name="velocity">
        <param name="min">-10</param>
        <param name="max">10</param>
      </command_interface>
      <state_interface name="position"/>
      <state_interface name="velocity"/>
      <state_interface name="effort"/>
    </joint>
    <joint name="rear_wheel_joint_right">
      <command_interface name="velocity">
        <param name="min">-10</param>
        <param name="max">10</param>
      </command_interface>
      <state_interface name="position"/>
      <state_interface name="velocity"/>
      <state_interface name="effort"/>
    </joint>
    <joint name="front_wheel_joint_left">
      <command_interface name="velocity">
        <param name="min">-10</param>
        <param name="max">10</param>
      </command_interface>
      <state_interface name="position"/>
      <state_interface name="velocity"/>
      <state_interface name="effort"/>
    </joint>
    <joint name="front_wheel_joint_right">
      <command_interface name="velocity">
        <param name="min">-10</param>
        <param name="max">10</param>
      </command_interface>
      <state_interface name="position"/>
      <state_interface name="velocity"/>
      <state_interface name="effort"/>
    </joint>
    <joint name="front_wheel_joint_R">
      <command_interface name="position">
        <param name="min">-5</param>
        <param name="max">5</param>
      </command_interface>
      <command_interface name="velocity">
        <param name="min">-0.1</param>
        <param name="max">0.1</param>
      </command_interface>
      <state_interface name="position"/>
      <state_interface name="velocity"/>
      <state_interface name="effort"/>
    </joint>
    <joint name="front_wheel_joint_L">
      <command_interface name="position">
        <param name="min">-5</param>
        <param name="max">5</param>
      </command_interface>
      <command_interface name="velocity">
        <param name="min">-0.1</param>
        <param name="max">0.1</param>
      </command_interface>
      <state_interface name="position"/>
      <state_interface name="velocity"/>
      <state_interface name="effort"/>
    </joint>
    <joint name="rear_wheel_joint_R">
      <command_interface name="position">
        <param name="min">-5</param>
        <param name="max">5</param>
      </command_interface>
      <command_interface name="velocity">
        <param name="min">-0.1</param>
        <param name="max">0.1</param>
      </command_interface>
      <state_interface name="position"/>
      <state_interface name="velocity"/>
      <state_interface name="effort"/>
    </joint>
    <joint name="rear_wheel_joint_L">
      <command_interface name="position">
        <param name="min">-5</param>
        <param name="max">5</param>
      </command_interface>
      <command_interface name="velocity">
        <param name="min">-0.1</param>
        <param name="max">0.1</param>
      </command_interface>
      <state_interface name="position"/>
      <state_interface name="velocity"/>
      <state_interface name="effort"/>
    </joint>
  </ros2_control>
  <gazebo>
    <plugin filename="libgazebo_ros2_control.so" name="gazebo_ros2_control">
      <parameters>/home/pi/osr_ws/install/osr_gazebo/share/osr_gazebo/config/controller_velocity.yaml</parameters>
    </plugin>
  </gazebo>
  <gazebo reference="imu_link">
    <gravity>true</gravity>
    <sensor name="imu_sensor" type="imu">
      <always_on>true</always_on>
      <update_rate>100</update_rate>
      <visualize>true</visualize>
      <topic>&quot;imu&quot;</topic>
      <plugin filename="libgazebo_ros_imu_sensor.so" name="imu_plugin">
        <topicName>imu</topicName>
        <bodyName>imu_link</bodyName>
        <updateRateHZ>100.0</updateRateHZ>
        <gaussianNoise>0.0</gaussianNoise>
        <xyzOffset>0 0 0</xyzOffset>
        <rpyOffset>0 0 0</rpyOffset>
        <frameName>imu_link</frameName>
        <initialOrientationAsReference>false</initialOrientationAsReference>
      </plugin>
      <pose>0 0 0 0 0 0</pose>
    </sensor>
  </gazebo>
  <link name="base_footprint"/>
  <link name="base_link">
    <collision>
      <origin rpy="0 0 0" xyz="0 0 0.0"/>
      <geometry>
        <mesh filename="file:///home/pi/osr_ws/install/osr_gazebo/share/osr_gazebo/meshes/body.stl"/>
      </geometry>
    </collision>
    <visual>
      <origin rpy="0 0 0" xyz="0 0 0.0"/>
      <geometry>
        <mesh filename="file:///home/pi/osr_ws/install/osr_gazebo/share/osr_gazebo/meshes/body.stl"/>
      </geometry>
      <material name="brown"/>
    </visual>
    <inertial>
      <origin rpy="0 0 0" xyz="0 0 0"/>
      <mass value="10"/>
      <inertia ixx="0.28541666666666665" ixy="0" ixz="0" iyy="0.8666666666666666" iyz="0" izz="1.0854166666666665"/>
    </inertial>
  </link>
  <joint name="base_joint" type="fixed">
    <parent link="base_footprint"/>
    <origin rpy="0 0 0" xyz="0 0 0.273745"/>
    <child link="base_link"/>
    <axis xyz="0 0 1"/>
  </joint>
  <link name="box_rotate">
    <collision>
      <origin rpy="0 0 -3.14" xyz="0 0 0.0"/>
      <geometry>
        <mesh filename="file:///home/pi/osr_ws/install/osr_gazebo/share/osr_gazebo/meshes/box_link.stl"/>
      </geometry>
    </collision>
    <visual>
      <origin rpy="0 0 -3.14" xyz="0 0 0"/>
      <geometry>
        <mesh filename="file:///home/pi/osr_ws/install/osr_gazebo/share/osr_gazebo/meshes/box_link.stl"/>
      </geometry>
      <material name="silver"/>
    </visual>
    <inertial>
      <origin rpy="0 0 -3.14" xyz="0 0 0"/>
      <mass value="0.2"/>
      <inertia ixx="0.0017960061392112761" ixy="0" ixz="0" iyy="5.164887871181532e-06" iyz="0" izz="0.001795990912371075"/>
    </inertial>
  </link>
  <joint name="body_joint" type="fixed">
    <parent link="base_link"/>
    <origin rpy="0 0 0" xyz="-0.071275 0 0.080475"/>
    <child link="box_rotate"/>
    <axis xyz="0 0 1"/>
  </joint>
  <link name="arm_rotate_L">
    <collision>
      <origin rpy="0 0.2 0" xyz="0 0 0"/>
      <geometry>
        <mesh filename="file:///home/pi/osr_ws/install/osr_gazebo/share/osr_gazebo/meshes/arm.stl"/>
      </geometry>
    </collision>
    <visual>
      <origin rpy="0 0.2 0" xyz="0 0 0"/>
      <geometry>
        <mesh filename="file:///home/pi/osr_ws/install/osr_gazebo/share/osr_gazebo/meshes/arm.stl"/>
      </geometry>
      <material name="silver"/>
    </visual>
    <inertial>
      <origin rpy="0 0.2 0" xyz="0 0 0"/>
      <mass value="0.1"/>
      <inertia ixx="3.1492026961385533e-06" ixy="0" ixz="0" iyy="6.396050780815705e-05" iyz="0" izz="6.393627133943758e-05"/>
    </inertial>
  </link>
  <joint name="arm_rotate_join_L" type="fixed">
    <parent link="box_rotate"/>
    <origin rpy="0 0.0 0" xyz="0 0.153 0"/>
    <child link="arm_rotate_L"/>
    <axis xyz="0 1 0"/>
  </joint>
  <link name="arm_rotate_R">
    <collision>
      <origin rpy="0 0.2 0" xyz="0 0 0"/>
      <geometry>
        <mesh filename="file:///home/pi/osr_ws/install/osr_gazebo/share/osr_gazebo/meshes/arm.stl"/>
      </geometry>
    </collision>
    <visual>
      <origin rpy="0 0.2 0" xyz="0 0 0"/>
      <geometry>
        <mesh filename="file:///home/pi/osr_ws/install/osr_gazebo/share/osr_gazebo/meshes/arm.stl"/>
      </geometry>
      <material name="silver"/>
    </visual>
    <inertial>
      <origin rpy="0 0.2 0" xyz="0 0 0"/>
      <mass value="0.1"/>
      <inertia ixx="3.1492026961385533e-06" ixy="0" ixz="0" iyy="6.396050780815705e-05" iyz="0" izz="6.393627133943758e-05"/>
    </inertial>
  </link>
  <joint name="arm_rotate_join_R" type="fixed">
    <parent link="box_rotate"/>
    <origin rpy="0 0.0 0" xyz="0 -0.153 0"/>
    <child link="arm_rotate_R"/>
    <axis xyz="0 1 0"/>
  </joint>
  <link name="turn_bukles_link_L">
    <collision>
      <origin rpy="0 0 0" xyz="0 0 0.0"/>
      <geometry>
        <mesh filename="file:///home/pi/osr_ws/install/osr_gazebo/share/osr_gazebo/meshes/turn_L.stl"/>
      </geometry>
    </collision>
    <visual>
      <origin rpy="0 0 0" xyz="0 0 0.0"/>
      <geometry>
        <mesh filename="file:///home/pi/osr_ws/install/osr_gazebo/share/osr_gazebo/meshes/turn_L.stl"/>
      </geometry>
      <material name="silver"/>
    </visual>
    <inertial>
      <origin rpy="0 0 0" xyz="0 0 0.0"/>
      <mass value="1"/>
      <inertia ixx="0.0016688655832571472" ixy="0" ixz="0" iyy="0.0020448255700570341" iyz="0" izz="0.00116395044451649"/>
    </inertial>
  </link>
  <joint name="turn_bukles_joint_L" type="fixed">
    <parent link="arm_rotate_L"/>
    <origin rpy="0 0 0" xyz="0.071558 0.017545 -0.084292"/>
    <child link="turn_bukles_link_L"/>
    <axis xyz="0 1 0"/>
  </joint>
  <link name="turn_bukles_link_R">
    <collision>
      <origin rpy="0 0 -1.57" xyz="0 0 0.0"/>
      <geometry>
        <mesh filename="file:///home/pi/osr_ws/install/osr_gazebo/share/osr_gazebo/meshes/turn_R.stl"/>
      </geometry>
    </collision>
    <visual>
      <origin rpy="0 0 -1.57" xyz="0 0 0.0"/>
      <geometry>
        <mesh filename="file:///home/pi/osr_ws/install/osr_gazebo/share/osr_gazebo/meshes/turn_R.stl"/>
      </geometry>
      <material name="silver"/>
    </visual>
    <inertial>
      <origin rpy="0 0 0" xyz="0 0 0.0"/>
      <mass value="1"/>
      <inertia ixx="0.0016688655832571472" ixy="0" ixz="0" iyy="0.0020448255700570341" iyz="0" izz="0.00116395044451649"/>
    </inertial>
  </link>
  <joint name="turn_bukles_joint_R" type="fixed">
    <parent link="arm_rotate_R"/>
    <origin rpy="0 0 0" xyz="0.071558 -0.017545 -0.084292"/>
    <child link="turn_bukles_link_R"/>
    <axis xyz="0 1 0"/>
  </joint>
  <link name="body_axis_link_L">
    <collision>
      <origin rpy="0 0 1.57" xyz="0 0 0.0"/>
      <geometry>
        <mesh filename="file:///home/pi/osr_ws/install/osr_gazebo/share/osr_gazebo/meshes/body_axis.stl"/>
      </geometry>
    </collision>
    <visual>
      <origin rpy="0 0 1.57" xyz="0 0 0.0"/>
      <geometry>
        <mesh filename="file:///home/pi/osr_ws/install/osr_gazebo/share/osr_gazebo/meshes/body_axis.stl"/>
      </geometry>
      <material name="silver"/>
    </visual>
    <inertial>
      <origin rpy="0 0 1.57" xyz="0 0 0.0"/>
      <mass value="0.5"/>
      <inertia ixx="0.0002647325735077617" ixy="0" ixz="0" iyy="0.0006894427883912008" iyz="0" izz="0.0007752858571736844"/>
    </inertial>
  </link>
  <joint name="body_axis_joint_L" type="fixed">
    <parent link="turn_bukles_link_L"/>
    <origin rpy="0 0 0" xyz="0 -0.06092 -0.001245"/>
    <child link="body_axis_link_L"/>
    <axis xyz="0 1 0"/>
  </joint>
  <link name="body_axis_link_R">
    <collision>
      <origin rpy="0 0 1.57" xyz="0 0 0.0"/>
      <geometry>
        <mesh filename="file:///home/pi/osr_ws/install/osr_gazebo/share/osr_gazebo/meshes/body_axis.stl"/>
      </geometry>
    </collision>
    <visual>
      <origin rpy="0 0 1.57" xyz="0 0 0.0"/>
      <geometry>
        <mesh filename="file:///home/pi/osr_ws/install/osr_gazebo/share/osr_gazebo/meshes/body_axis.stl"/>
      </geometry>
      <material name="silver"/>
    </visual>
    <inertial>
      <origin rpy="0 0 1.57" xyz="0 0 0.0"/>
      <mass value="0.5"/>
      <inertia ixx="0.0002647325735077617" ixy="0" ixz="0" iyy="0.0006894427883912008" iyz="0" izz="0.0007752858571736844"/>
    </inertial>
  </link>
  <joint name="body_axis_joint_R" type="fixed">
    <parent link="turn_bukles_link_R"/>
    <origin rpy="0 0 0" xyz="0 0.06092 -0.001245"/>
    <child link="body_axis_link_R"/>
    <axis xyz="0 1 0"/>
  </joint>
  <link name="rocker_bogie_link_L_1">
    <collision>
      <origin rpy="0 0 0" xyz="0 0 0.0"/>
      <geometry>
        <mesh filename="file:///home/pi/osr_ws/install/osr_gazebo/share/osr_gazebo/meshes/rockerbogie_middle_1.stl"/>
      </geometry>
    </collision>
    <visual>
      <origin rpy="0 0 0" xyz="0 0 0.0"/>
      <geometry>
        <mesh filename="file:///home/pi/osr_ws/install/osr_gazebo/share/osr_gazebo/meshes/rockerbogie_middle_1.stl"/>
      </geometry>
      <material name="silver"/>
    </visual>
    <inertial>
      <origin rpy="0 0 0" xyz="0 0 0.0"/>
      <mass value="7"/>
      <inertia ixx="0.24701126860819052" ixy="0" ixz="0" iyy="3.544526366681435" iyz="0" izz="3.335915098740816"/>
    </inertial>
  </link>
  <joint name="rocker_bogie_joint_L_1" type="fixed">
    <parent link="body_axis_link_L"/>
    <origin rpy="0 0 0" xyz="0.016004 0.071485 0.001353"/>
    <child link="rocker_bogie_link_L_1"/>
    <limit effort="10000.0" lower="-0.5" upper="0.5" velocity="0.5"/>
    <axis xyz="0 1 0"/>
  </joint>
  <link name="rocker_bogie_link_L_2">
    <collision>
      <origin rpy="0 0 0" xyz="0 0 0.0"/>
      <geometry>
        <mesh filename="file:///home/pi/osr_ws/install/osr_gazebo/share/osr_gazebo/meshes/rockerbogie_front_1.stl"/>
      </geometry>
    </collision>
    <visual>
      <origin rpy="0 0 0" xyz="0 0 0.0"/>
      <geometry>
        <mesh filename="file:///home/pi/osr_ws/install/osr_gazebo/share/osr_gazebo/meshes/rockerbogie_front_1.stl"/>
      </geometry>
      <material name="silver"/>
    </visual>
    <inertial>
      <origin rpy="0 0 0" xyz="0 0 0.0"/>
      <mass value="3"/>
      <inertia ixx="0.51733003028693055" ixy="0" ixz="0" iyy="1.1690895987181758" iyz="0" izz="0.6934262363396754"/>
    </inertial>
  </link>
  <joint name="rocker_bogie_joint_L_2" type="revolute">
    <parent link="rocker_bogie_link_L_1"/>
    <origin rpy="0 0 0" xyz="0.099618 0 -0.091275"/>
    <child link="rocker_bogie_link_L_2"/>
    <limit effort="10000.0" lower="-0.5" upper="0.5" velocity="1.0"/>
    <axis xyz="0 1 0"/>
  </joint>
  <link name="rocker_bogie_link_R_1">
    <collision>
      <origin rpy="0 0 0" xyz="0 0 0.0"/>
      <geometry>
        <mesh filename="file:///home/pi/osr_ws/install/osr_gazebo/share/osr_gazebo/meshes/rockerbogie_middle_1.stl"/>
      </geometry>
    </collision>
    <visual>
      <origin rpy="0 0 0" xyz="0 0 0.0"/>
      <geometry>
        <mesh filename="file:///home/pi/osr_ws/install/osr_gazebo/share/osr_gazebo/meshes/rockerbogie_middle_1.stl"/>
      </geometry>
      <material name="silver"/>
    </visual>
    <inertial>
      <origin rpy="0 0 0" xyz="0 0 0.0"/>
      <mass value="7"/>
      <inertia ixx="0.24701126860819052" ixy="0" ixz="0" iyy="3.544526366681435" iyz="0" izz="3.335915098740816"/>
    </inertial>
  </link>
  <joint name="rocker_bogie_joint_R_1" type="fixed">
    <parent link="body_axis_link_R"/>
    <origin rpy="0 0 0" xyz="0.016004 -0.071485 0.001353"/>
    <child link="rocker_bogie_link_R_1"/>
    <limit effort="10000.0" lower="-0.5" upper="0.5" velocity="0.5"/>
    <axis xyz="0 1 0"/>
  </joint>
  <link name="rocker_bogie_link_R_2">
    <collision>
      <origin rpy="0 0 0" xyz="0 0 0.0"/>
      <geometry>
        <mesh filename="file:///home/pi/osr_ws/install/osr_gazebo/share/osr_gazebo/meshes/rockerbogie_front_1.stl"/>
      </geometry>
    </collision>
    <visual>
      <origin rpy="0 0 0" xyz="0 0 0.0"/>
      <geometry>
        <mesh filename="file:///home/pi/osr_ws/install/osr_gazebo/share/osr_gazebo/meshes/rockerbogie_front_1.stl"/>
      </geometry>
      <material name="silver"/>
    </visual>
    <inertial>
      <origin rpy="0 0 0" xyz="0 0 0.0"/>
      <mass value="3"/>
      <inertia ixx="0.51733003028693055" ixy="0" ixz="0" iyy="1.1690895987181758" iyz="0" izz="0.6934262363396754"/>
    </inertial>
  </link>
  <joint name="rocker_bogie_joint_R_2" type="revolute">
    <parent link="rocker_bogie_link_R_1"/>
    <origin rpy="0 0 0" xyz="0.099618 0 -0.091275"/>
    <child link="rocker_bogie_link_R_2"/>
    <limit effort="10000.0" lower="-0.5" upper="0.5" velocity="1.0"/>
    <axis xyz="0 1 0"/>
  </joint>
  <link name="front_wheel_link_L">
    <collision>
      <origin rpy="0 0 -1.57" xyz="0 0 0.0"/>
      <geometry>
        <mesh filename="file:///home/pi/osr_ws/install/osr_gazebo/share/osr_gazebo/meshes/wheel_link_left_2.stl"/>
      </geometry>
    </collision>
    <visual>
      <origin rpy="0 0 -1.57" xyz="0 0 0.0"/>
      <geometry>
        <mesh filename="file:///home/pi/osr_ws/install/osr_gazebo/share/osr_gazebo/meshes/wheel_link_left_2.stl"/>
      </geometry>
      <material name="silver"/>
    </visual>
    <inertial>
      <origin rpy="0 0 -1.57" xyz="0 0 0.0"/>
      <mass value="0.8"/>
      <inertia ixx="0.002865290876023045" ixy="0" ixz="0" iyy="0.004329299643338258" iyz="0" izz="0.0018192303726865125"/>
    </inertial>
  </link>
  <joint name="front_wheel_joint_L" type="revolute">
    <!-- revolute continuous -->
    <parent link="rocker_bogie_link_L_2"/>
    <origin rpy="0 0 0" xyz="0.170113 -0.000335 0.076721"/>
    <child link="front_wheel_link_L"/>
    <limit effort="100000.0" lower="-0.523599" upper="0.523599" velocity="10"/>
    <axis xyz="0 0 1"/>
  </joint>
  <link name="middle_wheel_link_L">
    <collision>
      <origin rpy="1.57 0 -1.57" xyz="0 0 0.0"/>
      <geometry>
        <mesh filename="file:///home/pi/osr_ws/install/osr_gazebo/share/osr_gazebo/meshes/wheel_middle_left.stl"/>
      </geometry>
    </collision>
    <visual>
      <origin rpy="1.57 0 -1.57" xyz="0 0 0.0"/>
      <geometry>
        <mesh filename="file:///home/pi/osr_ws/install/osr_gazebo/share/osr_gazebo/meshes/wheel_middle_left.stl"/>
      </geometry>
      <material name="silver"/>
    </visual>
    <inertial>
      <origin rpy="1.57 0 -1.57" xyz="0 0 0.0"/>
      <mass value="0.3"/>
      <inertia ixx="0.00023039825512741194" ixy="0" ixz="0" iyy="0.0004706118439697759" iyz="0" izz="0.0004706117933937492"/>
    </inertial>
  </link>
  <joint name="middle_wheel_joint_L" type="fixed">
    <parent link="rocker_bogie_link_L_2"/>
    <origin rpy="0 0 0" xyz="-0.101456 5.3e-05 -0.100276"/>
    <child link="middle_wheel_link_L"/>
    <axis xyz="0 1 0"/>
  </joint>
  <link name="rear_wheel_link_L">
    <collision>
      <origin rpy="0 0 -1.57" xyz="0 0 0.0"/>
      <geometry>
        <mesh filename="file:///home/pi/osr_ws/install/osr_gazebo/share/osr_gazebo/meshes/wheel_link_left_2.stl"/>
      </geometry>
    </collision>
    <visual>
      <origin rpy="0 0 -1.57" xyz="0 0 0.0"/>
      <geometry>
        <mesh filename="file:///home/pi/osr_ws/install/osr_gazebo/share/osr_gazebo/meshes/wheel_link_left_2.stl"/>
      </geometry>
      <material name="silver"/>
    </visual>
    <inertial>
      <origin rpy="0 0 -1.57" xyz="0 0 0.0"/>
      <mass value="0.8"/>
      <inertia ixx="0.002865290876023045" ixy="0" ixz="0" iyy="0.004329299643338258" iyz="0" izz="0.0018192303726865125"/>
    </inertial>
  </link>
  <joint name="rear_wheel_joint_L" type="revolute">
    <!-- revolute continuous -->
    <parent link="rocker_bogie_link_L_1"/>
    <origin rpy="0 0 0" xyz="-0.311763 0 -0.030379"/>
    <child link="rear_wheel_link_L"/>
    <limit effort="100000.0" lower="-0.523599" upper="0.523599" velocity="3"/>
    <axis xyz="0 0 1"/>
  </joint>
  <link name="front_wheel_link_R">
    <collision>
      <origin rpy="0 0 1.57" xyz="0 0 0.0"/>
      <geometry>
        <mesh filename="file:///home/pi/osr_ws/install/osr_gazebo/share/osr_gazebo/meshes/wheel_link_left_2.stl"/>
      </geometry>
    </collision>
    <visual>
      <origin rpy="0 0 1.57" xyz="0 0 0.0"/>
      <geometry>
        <mesh filename="file:///home/pi/osr_ws/install/osr_gazebo/share/osr_gazebo/meshes/wheel_link_left_2.stl"/>
      </geometry>
      <material name="silver"/>
    </visual>
    <inertial>
      <origin rpy="0 0 1.57" xyz="0 0 0.0"/>
      <mass value="0.8"/>
      <inertia ixx="0.002865290876023045" ixy="0" ixz="0" iyy="0.004329299643338258" iyz="0" izz="0.0018192303726865125"/>
    </inertial>
  </link>
  <joint name="front_wheel_joint_R" type="revolute">
    <!-- revolute continuous -->
    <parent link="rocker_bogie_link_R_2"/>
    <origin rpy="0 0 0" xyz="0.170113 -0.000335 0.076721"/>
    <child link="front_wheel_link_R"/>
    <limit effort="100000.0" lower="-0.523599" upper="0.523599" velocity="10"/>
    <axis xyz="0 0 1"/>
  </joint>
  <link name="middle_wheel_link_R">
    <collision>
      <origin rpy="-3.14 0 1.57" xyz="0 0 0.0"/>
      <geometry>
        <mesh filename="file:///home/pi/osr_ws/install/osr_gazebo/share/osr_gazebo/meshes/wheel_middle_left.stl"/>
      </geometry>
    </collision>
    <visual>
      <origin rpy="-3.14 0 1.57" xyz="0 0 0.0"/>
      <geometry>
        <mesh filename="file:///home/pi/osr_ws/install/osr_gazebo/share/osr_gazebo/meshes/wheel_middle_left.stl"/>
      </geometry>
      <material name="silver"/>
    </visual>
    <inertial>
      <origin rpy="-3.14 0 1.57" xyz="0 0 0.0"/>
      <mass value="0.3"/>
      <inertia ixx="0.00023039825512741194" ixy="0" ixz="0" iyy="0.0004706118439697759" iyz="0" izz="0.0004706117933937492"/>
    </inertial>
  </link>
  <joint name="middle_wheel_joint_R" type="fixed">
    <parent link="rocker_bogie_link_R_2"/>
    <origin rpy="0 0 0" xyz="-0.101456 -5.3e-05 -0.100276"/>
    <child link="middle_wheel_link_R"/>
    <axis xyz="0 1 0"/>
  </joint>
  <link name="rear_wheel_link_R">
    <collision>
      <origin rpy="0 0 1.57" xyz="0 0 0.0"/>
      <geometry>
        <mesh filename="file:///home/pi/osr_ws/install/osr_gazebo/share/osr_gazebo/meshes/wheel_link_left_2.stl"/>
      </geometry>
    </collision>
    <visual>
      <origin rpy="0 0 1.57" xyz="0 0 0.0"/>
      <geometry>
        <mesh filename="file:///home/pi/osr_ws/install/osr_gazebo/share/osr_gazebo/meshes/wheel_link_left_2.stl"/>
      </geometry>
      <material name="silver"/>
    </visual>
    <inertial>
      <origin rpy="0 0 1.57" xyz="0 0 0.0"/>
      <mass value="0.8"/>
      <inertia ixx="0.002865290876023045" ixy="0" ixz="0" iyy="0.004329299643338258" iyz="0" izz="0.0018192303726865125"/>
    </inertial>
  </link>
  <joint name="rear_wheel_joint_R" type="revolute">
    <!-- revolute continuous -->
    <parent link="rocker_bogie_link_R_1"/>
    <origin rpy="0 0 0" xyz="-0.311763 0 -0.030379"/>
    <child link="rear_wheel_link_R"/>
    <limit effort="100000.0" lower="-0.523599" upper="0.523599" velocity="3"/>
    <axis xyz="0 0 1"/>
  </joint>
  <link name="front_wheel_link_left">
    <collision>
      <origin rpy="-1.57 0 0" xyz="0 0 0.0"/>
      <geometry>
        <mesh filename="file:///home/pi/osr_ws/install/osr_gazebo/share/osr_gazebo/meshes/wheel.stl"/>
      </geometry>
      <surface>
        <friction>
          <ode>
            <mu>0.7</mu>
            <mu2>0.3</mu2>
          </ode>
        </friction>
      </surface>
    </collision>
    <visual>
      <origin rpy="-1.57 0 0" xyz="0 0 0.0"/>
      <geometry>
        <mesh filename="file:///home/pi/osr_ws/install/osr_gazebo/share/osr_gazebo/meshes/wheel.stl"/>
      </geometry>
      <material name="black"/>
    </visual>
    <inertial>
      <origin rpy="-1.57 0 0" xyz="0 0 0.0"/>
      <mass value="0.8"/>
      <inertia ixx="0.0024621497157168697" ixy="0" ixz="0" iyy="0.002462972407314915" iyz="0" izz="0.0035658885464652456"/>
    </inertial>
  </link>
  <joint name="front_wheel_joint_left" type="continuous">
    <parent link="front_wheel_link_L"/>
    <origin rpy="0 0 0" xyz="0.006231 0.019544 -0.169991"/>
    <child link="front_wheel_link_left"/>
    <axis xyz="0 1 0"/>
    <velocity>5.0</velocity>
  </joint>
  <link name="middle_wheel_link_left">
    <collision>
      <origin rpy="-1.57 0 0" xyz="0 0 0.0"/>
      <geometry>
        <mesh filename="file:///home/pi/osr_ws/install/osr_gazebo/share/osr_gazebo/meshes/wheel.stl"/>
      </geometry>
      <surface>
        <friction>
          <ode>
            <mu>0.7</mu>
            <mu2>0.3</mu2>
          </ode>
        </friction>
      </surface>
    </collision>
    <visual>
      <origin rpy="-1.57 0 0" xyz="0 0 0.0"/>
      <geometry>
        <mesh filename="file:///home/pi/osr_ws/install/osr_gazebo/share/osr_gazebo/meshes/wheel.stl"/>
      </geometry>
      <material name="black"/>
    </visual>
    <inertial>
      <origin rpy="-1.57 0 0" xyz="0 0 0.0"/>
      <mass value="0.8"/>
      <inertia ixx="0.0024621497157168697" ixy="0" ixz="0" iyy="0.002462972407314915" iyz="0" izz="0.0035658885464652456"/>
    </inertial>
  </link>
  <joint name="middle_wheel_joint_left" type="continuous">
    <parent link="middle_wheel_link_L"/>
    <origin rpy="0 0 0" xyz="0.006691 0.100382 0.005425"/>
    <child link="middle_wheel_link_left"/>
    <axis xyz="0 1 0"/>
    <velocity>5.0</velocity>
  </joint>
  <link name="rear_wheel_link_left">
    <collision>
      <origin rpy="-1.57 0 0" xyz="0 0 0.0"/>
      <geometry>
        <mesh filename="file:///home/pi/osr_ws/install/osr_gazebo/share/osr_gazebo/meshes/wheel.stl"/>
      </geometry>
      <surface>
        <friction>
          <ode>
            <mu>0.7</mu>
            <mu2>0.3</mu2>
          </ode>
        </friction>
      </surface>
    </collision>
    <visual>
      <origin rpy="-1.57 0 0" xyz="0 0 0.0"/>
      <geometry>
        <mesh filename="file:///home/pi/osr_ws/install/osr_gazebo/share/osr_gazebo/meshes/wheel.stl"/>
      </geometry>
      <material name="black"/>
    </visual>
    <inertial>
      <origin rpy="-1.57 0 0" xyz="0 0 0.0"/>
      <mass value="0.8"/>
      <inertia ixx="0.0024621497157168697" ixy="0" ixz="0" iyy="0.002462972407314915" iyz="0" izz="0.0035658885464652456"/>
    </inertial>
  </link>
  <joint name="rear_wheel_joint_left" type="continuous">
    <parent link="rear_wheel_link_L"/>
    <origin rpy="0 0 0" xyz="-0.000203 0.008131 -0.160678"/>
    <child link="rear_wheel_link_left"/>
    <axis xyz="0 1 0"/>
    <velocity>5.0</velocity>
  </joint>
  <link name="front_wheel_link_right">
    <collision>
      <origin rpy="-1.57 0 3.14" xyz="0 0 0.0"/>
      <geometry>
        <mesh filename="file:///home/pi/osr_ws/install/osr_gazebo/share/osr_gazebo/meshes/wheel.stl"/>
      </geometry>
      <surface>
        <friction>
          <ode>
            <mu>0.7</mu>
            <mu2>0.3</mu2>
          </ode>
        </friction>
      </surface>
    </collision>
    <visual>
      <origin rpy="-1.57 0 3.14" xyz="0 0 0.0"/>
      <geometry>
        <mesh filename="file:///home/pi/osr_ws/install/osr_gazebo/share/osr_gazebo/meshes/wheel.stl"/>
      </geometry>
      <material name="black"/>
    </visual>
    <inertial>
      <origin rpy="-1.57 0 3.14" xyz="0 0 0.0"/>
      <mass value="0.8"/>
      <inertia ixx="0.0024621497157168697" ixy="0" ixz="0" iyy="0.002462972407314915" iyz="0" izz="0.0035658885464652456"/>
    </inertial>
  </link>
  <joint name="front_wheel_joint_right" type="continuous">
    <parent link="front_wheel_link_R"/>
    <origin rpy="0 0 0" xyz="0.006231 -0.019544 -0.169991"/>
    <child link="front_wheel_link_right"/>
    <axis xyz="0 1 0"/>
    <velocity>5.0</velocity>
  </joint>
  <link name="middle_wheel_link_right">
    <collision>
      <origin rpy="-1.57 0 3.14" xyz="0 0 0.0"/>
      <geometry>
        <mesh filename="file:///home/pi/osr_ws/install/osr_gazebo/share/osr_gazebo/meshes/wheel.stl"/>
      </geometry>
      <surface>
        <friction>
          <ode>
            <mu>0.7</mu>
            <mu2>0.3</mu2>
          </ode>
        </friction>
      </surface>
    </collision>
    <visual>
      <origin rpy="-1.57 0 3.14" xyz="0 0 0.0"/>
      <geometry>
        <mesh filename="file:///home/pi/osr_ws/install/osr_gazebo/share/osr_gazebo/meshes/wheel.stl"/>
      </geometry>
      <material name="black"/>
    </visual>
    <inertial>
      <origin rpy="-1.57 0 3.14" xyz="0 0 0.0"/>
      <mass value="0.8"/>
      <inertia ixx="0.0024621497157168697" ixy="0" ixz="0" iyy="0.002462972407314915" iyz="0" izz="0.0035658885464652456"/>
    </inertial>
  </link>
  <joint name="middle_wheel_joint_right" type="continuous">
    <parent link="middle_wheel_link_R"/>
    <origin rpy="0 0 0" xyz="0.006691 -0.100382 0.005425"/>
    <child link="middle_wheel_link_right"/>
    <axis xyz="0 1 0"/>
    <velocity>5.0</velocity>
  </joint>
  <link name="rear_wheel_link_right">
    <collision>
      <origin rpy="-1.57 0 3.14" xyz="0 0 0.0"/>
      <geometry>
        <mesh filename="file:///home/pi/osr_ws/install/osr_gazebo/share/osr_gazebo/meshes/wheel.stl"/>
      </geometry>
      <surface>
        <friction>
          <ode>
            <mu>0.7</mu>
            <mu2>0.3</mu2>
          </ode>
        </friction>
      </surface>
    </collision>
    <visual>
      <origin rpy="-1.57 0 3.14" xyz="0 0 0.0"/>
      <geometry>
        <mesh filename="file:///home/pi/osr_ws/install/osr_gazebo/share/osr_gazebo/meshes/wheel.stl"/>
      </geometry>
      <material name="black"/>
    </visual>
    <inertial>
      <origin rpy="-1.57 0 3.14" xyz="0 0 0.0"/>
      <mass value="0.8"/>
      <inertia ixx="0.0024621497157168697" ixy="0" ixz="0" iyy="0.002462972407314915" iyz="0" izz="0.0035658885464652456"/>
    </inertial>
  </link>
  <joint name="rear_wheel_joint_right" type="continuous">
    <parent link="rear_wheel_link_R"/>
    <origin rpy="0 0 0" xyz="-0.000203 -0.008131 -0.160678"/>
    <child link="rear_wheel_link_right"/>
    <axis xyz="0 1 0"/>
    <velocity>5.0</velocity>
  </joint>
  <joint name="imu_joint" type="fixed">
    <parent link="base_link"/>
    <child link="imu_link"/>
    <origin rpy="0 0 0" xyz="0 0 0"/>
  </joint>
  <link name="imu_link"/>
  <transmission name="rear_wheel_joint_right_tran">
    <type>transmission_interface/SimpleTransmission</type>
    <joint name="rear_wheel_joint_right">
      <hardwareInterface>VelocityJointInterface</hardwareInterface>
      <!-- Updated for ROS2 -->
      <mechanicalReduction>1</mechanicalReduction>
    </joint>
    <actuator name="rear_wheel_joint_right_motor">
      <hardwareInterface>VelocityJointInterface</hardwareInterface>
      <!-- Updated for ROS2 -->
      <mechanicalReduction>1</mechanicalReduction>
    </actuator>
  </transmission>
  <transmission name="rear_wheel_joint_left_tran">
    <type>transmission_interface/SimpleTransmission</type>
    <joint name="rear_wheel_joint_left">
      <hardwareInterface>VelocityJointInterface</hardwareInterface>
      <!-- Updated for ROS2 -->
      <mechanicalReduction>1</mechanicalReduction>
    </joint>
    <actuator name="rear_wheel_joint_left_motor">
      <hardwareInterface>VelocityJointInterface</hardwareInterface>
      <!-- Updated for ROS2 -->
      <mechanicalReduction>1</mechanicalReduction>
    </actuator>
  </transmission>
  <transmission name="middle_wheel_joint_right_tran">
    <type>transmission_interface/SimpleTransmission</type>
    <joint name="middle_wheel_joint_right">
      <hardwareInterface>VelocityJointInterface</hardwareInterface>
      <!-- Updated for ROS2 -->
      <mechanicalReduction>1</mechanicalReduction>
    </joint>
    <actuator name="middle_wheel_joint_right_motor">
      <hardwareInterface>VelocityJointInterface</hardwareInterface>
      <!-- Updated for ROS2 -->
      <mechanicalReduction>1</mechanicalReduction>
    </actuator>
  </transmission>
  <transmission name="middle_wheel_joint_left_tran">
    <type>transmission_interface/SimpleTransmission</type>
    <joint name="middle_wheel_joint_left">
      <hardwareInterface>VelocityJointInterface</hardwareInterface>
      <!-- Updated for ROS2 -->
      <mechanicalReduction>1</mechanicalReduction>
    </joint>
    <actuator name="middle_wheel_joint_left_motor">
      <hardwareInterface>VelocityJointInterface</hardwareInterface>
      <!-- Updated for ROS2 -->
      <mechanicalReduction>1</mechanicalReduction>
    </actuator>
  </transmission>
  <transmission name="front_wheel_joint_right_tran">
    <type>transmission_interface/SimpleTransmission</type>
    <joint name="front_wheel_joint_right">
      <hardwareInterface>VelocityJointInterface</hardwareInterface>
      <!-- Updated for ROS2 -->
      <mechanicalReduction>1</mechanicalReduction>
    </joint>
    <actuator name="front_wheel_joint_right_motor">
      <hardwareInterface>VelocityJointInterface</hardwareInterface>
      <!-- Updated for ROS2 -->
      <mechanicalReduction>1</mechanicalReduction>
    </actuator>
  </transmission>
  <transmission name="front_wheel_joint_left_tran">
    <type>transmission_interface/SimpleTransmission</type>
    <joint name="front_wheel_joint_left">
      <hardwareInterface>VelocityJointInterface</hardwareInterface>
      <!-- Updated for ROS2 -->
      <mechanicalReduction>1</mechanicalReduction>
    </joint>
    <actuator name="front_wheel_joint_left_motor">
      <hardwareInterface>VelocityJointInterface</hardwareInterface>
      <!-- Updated for ROS2 -->
      <mechanicalReduction>1</mechanicalReduction>
    </actuator>
  </transmission>
  <transmission name="front_wheel_joint_R_tran">
    <type>transmission_interface/SimpleTransmission</type>
    <joint name="front_wheel_joint_R">
      <hardwareInterface>PositionJointInterface</hardwareInterface>
      <!-- Updated for ROS2 -->
      <mechanicalReduction>1</mechanicalReduction>
    </joint>
    <actuator name="front_wheel_joint_R_motor">
      <hardwareInterface>PositionJointInterface</hardwareInterface>
      <!-- Updated for ROS2 -->
      <mechanicalReduction>1</mechanicalReduction>
    </actuator>
  </transmission>
  <transmission name="front_wheel_joint_L_tran">
    <type>transmission_interface/SimpleTransmission</type>
    <joint name="front_wheel_joint_L">
      <hardwareInterface>PositionJointInterface</hardwareInterface>
      <!-- Updated for ROS2 -->
      <mechanicalReduction>1</mechanicalReduction>
    </joint>
    <actuator name="front_wheel_joint_L_motor">
      <hardwareInterface>PositionJointInterface</hardwareInterface>
      <!-- Updated for ROS2 -->
      <mechanicalReduction>1</mechanicalReduction>
    </actuator>
  </transmission>
  <transmission name="rear_wheel_joint_R_tran">
    <type>transmission_interface/SimpleTransmission</type>
    <joint name="rear_wheel_joint_R">
      <hardwareInterface>PositionJointInterface</hardwareInterface>
      <!-- Updated for ROS2 -->
      <mechanicalReduction>1</mechanicalReduction>
    </joint>
    <actuator name="rear_wheel_joint_R_motor">
      <hardwareInterface>PositionJointInterface</hardwareInterface>
      <!-- Updated for ROS2 -->
      <mechanicalReduction>1</mechanicalReduction>
    </actuator>
  </transmission>
  <transmission name="rear_wheel_joint_L_tran">
    <type>transmission_interface/SimpleTransmission</type>
    <joint name="rear_wheel_joint_L">
      <hardwareInterface>PositionJointInterface</hardwareInterface>
      <!-- Updated for ROS2 -->
      <mechanicalReduction>1</mechanicalReduction>
    </joint>
    <actuator name="rear_wheel_joint_L_motor">
      <hardwareInterface>PositionJointInterface</hardwareInterface>
      <!-- Updated for ROS2 -->
      <mechanicalReduction>1</mechanicalReduction>
    </actuator>
  </transmission>
</robot>
